Workbook

Sheet P&L Summary
B2: 2020–2025 H1: actual data (from Annual Reports)
B3: Year | C3: Revenue | D3: EBITDA | E3: EBIT | F3: D&A | G3: CapEx | H3: FCF
B4: 2020 | C4: 684 | D4: 402 | E4: 374 | F4: 29 | G4: 22 | H4: 371
B5: 2021 | C5: 1002 | D5: 630 | E5: 595 | F5: 35 | G5: 54 | H5: 567
B6: 2022 | C6: 1330 | D6: 728 | E6: 665 | F6: 64 | G6: 99 | H6: 607
B7: 2023 | C7: 1626 | D7: 743 | E7: 658 | F7: 85 | G7: 70 | H7: 639
B8: 2024 | C8: 1996 | D8: 992 | E8: 888 | F8: 104 | G8: 91 | H8: 860
B9: H1 2025 | C9: 1093 | D9: 544 | E9: 483 | F9: 61 | G9: 47 | H9: 474
B12: Historical Margins Table (Adyen)
B13: Year | C13: EBITDA % | D13: EBIT % | E13: D&A % | F13: CapEx % | G13: FCF/EBITDA
B14: 2020 | C14: =D4/C4 -> 0.5877193 | D14: =E4/C4 -> 0.54678363 | E14: =F4/C4 -> 0.042397661 | F14: =G4/C4 -> 0.032163743 | G14: =H4/D4 -> 0.92288557
B15: 2021 | C15: =D5/C5 -> 0.62874251 | D15: =E5/C5 -> 0.59381238 | E15: =F5/C5 -> 0.03493014 | F15: =G5/C5 -> 0.053892216 | G15: =H5/D5 -> 0.9
B16: 2022 | C16: =D6/C6 -> 0.54736842 | D16: =E6/C6 -> 0.5 | E16: =F6/C6 -> 0.048120301 | F16: =G6/C6 -> 0.07443609 | G16: =H6/D6 -> 0.83379121
B17: 2023 | C17: =D7/C7 -> 0.45694957 | D17: =E7/C7 -> 0.40467405 | E17: =F7/C7 -> 0.052275523 | F17: =G7/C7 -> 0.043050431 | G17: =H7/D7 -> 0.86002692
B18: 2024 | C18: =D8/C8 -> 0.49699399 | D18: =E8/C8 -> 0.44488978 | E18: =F8/C8 -> 0.052104208 | F18: =G8/C8 -> 0.045591182 | G18: =H8/D8 -> 0.86693548
B19: AVG | C19: =AVERAGE(C14:C17) -> 0.55519495 | D19: =AVERAGE(D14:D17) -> 0.51131751 | E19: =AVERAGE(E14:E17) -> 0.044430906 | F19: =AVERAGE(F14:F17) -> 0.05088562 | G19: =AVERAGE(G14:G17) -> 0.87917592
B21: Historical basis (fact)
B22: Year | C22: Revenue (€m) | D22: YoY
B23: 2020 | C23: 684 | D23: —
B24: 2021 | C24: 1002 | D24: 0.46
B25: 2022 | C25: 1330 | D25: 0.33
B26: 2023 | C26: 1626 | D26: 0.22
B27: 2024 | C27: 1996 | D27: 0.23
B28: H1 2025 | C28: 1093 | D28: 0.21

Sheet FCF Forecast
B3: Base Case Growth Assumptions
B4: Year | C4: Growth | D4: Reason
B5: 2026E | C5: 0.15 | D5: scale + share gains
B6: 2027E | C6: 0.13 | D6: нормализация
B7: 2028E | C7: 0.11 | D7: mature growth
B10: Year | C10: Revenue (€m) | D10: YoY | F10: Revenue_2026 = Revenue_2025 * (1 + 15%)
B11: 2024A | C11: 1996 | D11: — | F11: Revenue_2027 = Revenue_2026 * (1 + 13%)
B12: 2025E | C12: 2187 | D12: 0.1 | F12: Revenue_2028 = Revenue_2027 * (1 + 11%)
B13: 2026E | C13: 2521 | D13: 0.15
B14: 2027E | C14: 2848 | D14: 0.13
B15: 2028E | C15: 3158 | D15: 0.11
B21: Year | C21: EBITDA | D21: D&A | E21: EBIT | F21: Cash Taxes | G21: CapEx | H21: ΔWorking Capital | I21: FCF (€m) | J21: FCF/EBITDA
B22: 2025E | C22: =C12*'P&L Summary'!$C$19 -> 1214.2114 | D22: =C12*'P&L Summary'!$E$19 -> 97.170391 | E22: =C22-D22 -> 1117.041 | F22: =E22*25% -> 279.26024 | G22: =C12*'P&L Summary'!$F$19 -> 111.28685 | H22: 0 | I22: =E22-F22+D22-G22-H22 -> 823.66427 | J22: =I22/C22 -> 0.67835329
B23: 2026E | C23: =C13*'P&L Summary'!$C$19 -> 1399.6465 | D23: =C13*'P&L Summary'!$E$19 -> 112.01031 | E23: =C23-D23 -> 1287.6362 | F23: =E23*25% -> 321.90904 | G23: =C13*'P&L Summary'!$F$19 -> 128.28265 | H23: 0 | I23: =E23-F23+D23-G23-H23 -> 949.45478 | J23: =I23/C23 -> 0.67835329
B24: 2027E | C24: =C14*'P&L Summary'!$C$19 -> 1581.1952 | D24: =C14*'P&L Summary'!$E$19 -> 126.53922 | E24: =C24-D24 -> 1454.656 | F24: =E24*25% -> 363.664 | G24: =C14*'P&L Summary'!$F$19 -> 144.92225 | H24: 0 | I24: =E24-F24+D24-G24-H24 -> 1072.609 | J24: =I24/C24 -> 0.67835329
B25: 2028E | C25: =C15*'P&L Summary'!$C$19 -> 1753.3057 | D25: =C15*'P&L Summary'!$E$19 -> 140.3128 | E25: =C25-D25 -> 1612.9929 | F25: =E25*25% -> 403.24821 | G25: =C15*'P&L Summary'!$F$19 -> 160.69679 | H25: 0 | I25: =E25-F25+D25-G25-H25 -> 1189.3607 | J25: =I25/C25 -> 0.67835329

Sheet DCF
B3: Year | C3: t | D3: DF | E3: PV FCF (€m) | G3: Parameter | H3: Value
B4: 2025E | C4: 1 | D4: =1/(1+$H$4)^C4 -> 0.91911765 | E4: ='FCF Forecast'!I22*DCF!D4 -> 757.04436 | G4: WACC | H4: 0.088
B5: 2026E | C5: 2 | D5: =1/(1+$H$4)^C5 -> 0.84477725 | E5: ='FCF Forecast'!I23*DCF!D5 -> 802.0778 | G5: g | H5: 0.025
B6: 2027E | C6: 3 | D6: =1/(1+$H$4)^C6 -> 0.77644968 | E6: ='FCF Forecast'!I24*DCF!D6 -> 832.82689 | G6: Base year | H6: 2024
B7: 2028E | C7: 4 | D7: =1/(1+$H$4)^C7 -> 0.7136486 | E7: ='FCF Forecast'!I25*DCF!D7 -> 848.78557
B10: Terminal Value (Gordon Growth)
B11: ='FCF Forecast'!I25*(1+H5)/(H4-H5) -> 19350.709
B12: PV of TV
B13: =B11*D7 -> 13809.606
B14: Enterprise Value (EV)
B15: =SUM(E4:E7)+B13 -> 17050.341
B18: Sensitivity Analysis — EV (WACC × g) | H18: Cash & cash equivalents + short-term investments
H19: 6500
B20: WACC \ g | C20: 0.02 | D20: 0.025 | E20: 0.03 | H20: Equity Value
B21: 0.08 | C21: =SUM($E$4:$E$7)+(('FCF Forecast'!$I$25*(1+C$20))/($B21-C$20))*$D$7 -> 17670.089 | D21: =SUM($E$4:$E$7)+(('FCF Forecast'!$I$25*(1+D$20))/($B21-D$20))*$D$7 -> 19059.011 | E21: =SUM($E$4:$E$7)+(('FCF Forecast'!$I$25*(1+E$20))/($B21-E$20))*$D$7 -> 20725.717 | H21: =B15+H19 -> 23550.341
B22: 0.085 | C22: =SUM($E$4:$E$7)+(('FCF Forecast'!$I$25*(1+C$20))/($B22-C$20))*$D$7 -> 16560.139 | D22: =SUM($E$4:$E$7)+(('FCF Forecast'!$I$25*(1+D$20))/($B22-D$20))*$D$7 -> 17740.821 | E22: =SUM($E$4:$E$7)+(('FCF Forecast'!$I$25*(1+E$20))/($B22-E$20))*$D$7 -> 19136.173 | H22: Shares outstanding
B23: 0.088 | C23: =SUM($E$4:$E$7)+(('FCF Forecast'!$I$25*(1+C$20))/($B23-C$20))*$D$7 -> 15972.518 | D23: =SUM($E$4:$E$7)+(('FCF Forecast'!$I$25*(1+D$20))/($B23-D$20))*$D$7 -> 17050.341 | E23: =SUM($E$4:$E$7)+(('FCF Forecast'!$I$25*(1+E$20))/($B23-E$20))*$D$7 -> 18313.996 | H23: 31.4
B24: 0.09 | C24: =SUM($E$4:$E$7)+(('FCF Forecast'!$I$25*(1+C$20))/($B24-C$20))*$D$7 -> 15608.753 | D24: =SUM($E$4:$E$7)+(('FCF Forecast'!$I$25*(1+D$20))/($B24-D$20))*$D$7 -> 16625.43 | E24: =SUM($E$4:$E$7)+(('FCF Forecast'!$I$25*(1+E$20))/($B24-E$20))*$D$7 -> 17811.554 | H24: Price per share
B25: 0.095 | C25: =SUM($E$4:$E$7)+(('FCF Forecast'!$I$25*(1+C$20))/($B25-C$20))*$D$7 -> 14784.218 | D25: =SUM($E$4:$E$7)+(('FCF Forecast'!$I$25*(1+D$20))/($B25-D$20))*$D$7 -> 15669.38 | E25: =SUM($E$4:$E$7)+(('FCF Forecast'!$I$25*(1+E$20))/($B25-E$20))*$D$7 -> 16690.721 | H25: =H21/H23 -> 750.01086
B28: DCF Sensitivity (WACC × g)
B30: Equity Value (€m)
B31: WACC \ g | C31: 0.02 | D31: 0.025 | E31: 0.03
B32: 0.08 | C32: =C21+$H$19 -> 24170.089 | D32: =D21+$H$19 -> 25559.011 | E32: =E21+$H$19 -> 27225.717
B33: 0.085 | C33: =C22+$H$19 -> 23060.139 | D33: =D22+$H$19 -> 24240.821 | E33: =E22+$H$19 -> 25636.173
B34: 0.088 | C34: =C23+$H$19 -> 22472.518 | D34: =D23+$H$19 -> 23550.341 | E34: =E23+$H$19 -> 24813.996
B35: 0.09 | C35: =C24+$H$19 -> 22108.753 | D35: =D24+$H$19 -> 23125.43 | E35: =E24+$H$19 -> 24311.554
B36: 0.095 | C36: =C25+$H$19 -> 21284.218 | D36: =D25+$H$19 -> 22169.38 | E36: =E25+$H$19 -> 23190.721
B38: Price per share (€)
B39: WACC \ g | C39: 0.02 | D39: 0.025 | E39: 0.03
B40: 0.08 | C40: =C32/$H$23 -> 769.74807 | D40: =D32/$H$23 -> 813.98125 | E40: =E32/$H$23 -> 867.06106
B41: 0.085 | C41: =C33/$H$23 -> 734.39933 | D41: =D33/$H$23 -> 772.00068 | E41: =E33/$H$23 -> 816.43864
B42: 0.088 | C42: =C34/$H$23 -> 715.68529 | D42: =D34/$H$23 -> 750.01086 | E42: =E34/$H$23 -> 790.25464
B43: 0.09 | C43: =C35/$H$23 -> 704.10041 | D43: =D35/$H$23 -> 736.47867 | E43: =E35/$H$23 -> 774.2533
B44: 0.095 | C44: =C36/$H$23 -> 677.84135 | D44: =D36/$H$23 -> 706.03122 | E44: =E36/$H$23 -> 738.558
H47: Based on a DCF valuation using a base-case WACC of 8.8% and terminal growth of 2.5%, Adyen’s intrinsic equity value is estimated at approximately €750 per share. This implies that the stock currently trades at a significant premium to our base-case valuation, reflecting either more optimistic long-term growth assumptions or a structurally lower cost of capital priced in by the market. | J47: 🔹 A) Market assumes much higher long-term growth • g скорее 3.5–4.0%, а не 2.5% • Adyen = “compounder for decades” 🔹 B) Market prices lower WACC • perceived risk ↓ • quasi-infrastructure payments asset • WACC ближе к 7–7.5% 🔹 C) DCF does not capture optionality • embedded finance • platform economics • operating leverage beyond explicit forecast
B48: Scenario | C48: WACC | D48: g | E48: Price (€) | F48: Upside / Downside
B49: Bear | C49: 0.095 | D49: 0.02 | E49: ~678 | F49: –56%
B50: Base | C50: 0.088 | D50: 0.025 | E50: ~750 | F50: –51%
B51: Bull | C51: 0.08 | D51: 0.03 | E51: ~867 | F51: –43%
B52: Market implied | C52: ~? | D52: ~? | E52: 1526 | F52: —
...
